Workbook

Sheet 00_README
A1: ITR — Detailed Feature List (4-Week POC) — v2
A2: v2 · 3 August 2026 · 137 features across 16 epics · Scope contract for the demo swim lane · Owner: Aamit Lakhani, Architect (AI)
A4: PURPOSE | B4: The scope contract for the 4-week POC. If a piece of work is not in 02_Feature_List, it is not in scope. Anything added must be logged as a change request and costed against remaining buffer.
A5: SCOPE STATEMENT | B5: Phase 1 of the DEMO swim lane confirmed 29-Jul-2026. Recommendation-only: the system classifies and states intention; every write passes a human gate. This is NOT the 10–12 week sellable MVP.
A6: WHAT CHANGED IN v2 | B6: Six source systems are EMULATED rather than one integrated — each with a faithful replica of its native schema plus a mock API speaking real endpoint shapes, pagination, rate limits and error codes. The corpus is generated INTO those native shapes and ingested through the real adapters. The live Zendesk sandbox is dropped. Analysts gain org, skills, measured handling history and derived capability signals (epic E15). Voice runs a full audio pipeline with real ASR (epic E16). 30 new features; the demo grows from 7 scenes to 8.
A8: SHEET GUIDE
A9: 01_Summary | B9: Counts and effort by epic, priority and owner. All formulas over 02_Feature_List.
A10: 02_Feature_List | B10: THE LIST. 137 features, each with a user story, Given/When/Then acceptance criteria, layer, component, dependency, priority, owner, week, success metric, demo scene and the plan task IDs that deliver it.
A11: 03_Epics | B11: The 16 epics with their owner and the MoM decision each traces back to.
A12: 04_Agent_Specs | B12: The 12-agent pipeline: inputs, outputs, model tier, guardrails, HITL gate and evaluation metric for each.
A13: 05_Data_Entities | B13: Canonical entities with their source mapping and POC volumes.
A14: 06_Integrations_APIs | B14: Zendesk endpoints and scopes, Workday bridge, Anthropic, and the rate limits that constrain design.
A15: 07_NonFunctional | B15: Performance, security, governance, observability and deployment targets with how each is measured.
A16: 08_Metrics_KPIs | B16: Every metric quoted anywhere in this programme, with its target, how it is measured and when it is first reported.
A17: 09_Out_of_Scope | B17: What is deliberately excluded, and the decision that excluded it. Read this before agreeing to anything in a meeting.
A18: 10_Source_Systems | B18: The six emulated systems: native objects modelled, API behaviour reproduced, adapter scope and what each contributes to the demo.
A20: PRIORITY KEY | B20: Must = the demo does not work without it · Should = the demo is materially weaker without it · Could = included only if buffer allows · Won't = explicitly excluded (see 09_Out_of_Scope).
A21: STATUS KEY | B21: Not started · In progress · In review · Done · Descoped. Update the yellow Status column; 01_Summary follows automatically.
... A23: TRACEABILITY | B23: The final column maps every feature to the task IDs in ITR_POC_ProjectPlan_v2_3Aug2026.xlsx that deliver it. Nothing in the plan is unattached to a feature, and nothing here is unattached to a task.

Sheet 01_Summary
A1: Feature Summary
A2: Every figure is a formula over 02_Feature_List. Update Status there; this follows.
A4: A. By epic
A5: Epic | B5: Name | C5: Features | D5: Must | E5: Should | F5: Could | G5: Done | H5: % done
A6: E01 | B6: Platform & Deployment | C6: =COUNTIF('02_Feature_List'!$B$5:$B$141,$A6) -> 9 | D6: =COUNTIFS('02_Feature_List'!$B$5:$B$141,$A6,'02_Feature_List'!$J$5:$J$141,"Must") -> 8 | E6: =COUNTIFS('02_Feature_List'!$B$5:$B$141,$A6,'02_Feature_List'!$J$5:$J$141,"Should") -> 1 | F6: =COUNTIFS('02_Feature_List'!$B$5:$B$141,$A6,'02_Feature_List'!$J$5:$J$141,"Could") -> 0 | G6: =COUNTIFS('02_Feature_List'!$B$5:$B$141,$A6,'02_Feature_List'!$Q$5:$Q$141,"Done") -> 0 | H6: =IFERROR(G6/C6,0) -> 0
A7: E02 | B7: Synthetic Data Corpus | C7: =COUNTIF('02_Feature_List'!$B$5:$B$141,$A7) -> 14 | D7: =COUNTIFS('02_Feature_List'!$B$5:$B$141,$A7,'02_Feature_List'!$J$5:$J$141,"Must") -> 11 | E7: =COUNTIFS('02_Feature_List'!$B$5:$B$141,$A7,'02_Feature_List'!$J$5:$J$141,"Should") -> 3 | F7: =COUNTIFS('02_Feature_List'!$B$5:$B$141,$A7,'02_Feature_List'!$J$5:$J$141,"Could") -> 0 | G7: =COUNTIFS('02_Feature_List'!$B$5:$B$141,$A7,'02_Feature_List'!$Q$5:$Q$141,"Done") -> 0 | H7: =IFERROR(G7/C7,0) -> 0
A8: E03 | B8: Canonical Model & Digital Twin | C8: =COUNTIF('02_Feature_List'!$B$5:$B$141,$A8) -> 8 | D8: =COUNTIFS('02_Feature_List'!$B$5:$B$141,$A8,'02_Feature_List'!$J$5:$J$141,"Must") -> 7 | E8: =COUNTIFS('02_Feature_List'!$B$5:$B$141,$A8,'02_Feature_List'!$J$5:$J$141,"Should") -> 1 | F8: =COUNTIFS('02_Feature_List'!$B$5:$B$141,$A8,'02_Feature_List'!$J$5:$J$141,"Could") -> 0 | G8: =COUNTIFS('02_Feature_List'!$B$5:$B$141,$A8,'02_Feature_List'!$Q$5:$Q$141,"Done") -> 0 | H8: =IFERROR(G8/C8,0) -> 0
A9: E04 | B9: Source Systems, Emulation & Ingestion | C9: =COUNTIF('02_Feature_List'!$B$5:$B$141,$A9) -> 25 | D9: =COUNTIFS('02_Feature_List'!$B$5:$B$141,$A9,'02_Feature_List'!$J$5:$J$141,"Must") -> 22 | E9: =COUNTIFS('02_Feature_List'!$B$5:$B$141,$A9,'02_Feature_List'!$J$5:$J$141,"Should") -> 3 | F9: =COUNTIFS('02_Feature_List'!$B$5:$B$141,$A9,'02_Feature_List'!$J$5:$J$141,"Could") -> 0 | G9: =COUNTIFS('02_Feature_List'!$B$5:$B$141,$A9,'02_Feature_List'!$Q$5:$Q$141,"Done") -> 0 | H9: =IFERROR(G9/C9,0) -> 0
A10: E05 | B10: Identity Resolution & 360 | C10: =COUNTIF('02_Feature_List'!$B$5:$B$141,$A10) -> 5 | D10: =COUNTIFS('02_Feature_List'!$B$5:$B$141,$A10,'02_Feature_List'!$J$5:$J$141,"Must") -> 3 | E10: =COUNTIFS('02_Feature_List'!$B$5:$B$141,$A10,'02_Feature_List'!$J$5:$J$141,"Should") -> 1 | F10: =COUNTIFS('02_Feature_List'!$B$5:$B$141,$A10,'02_Feature_List'!$J$5:$J$141,"Could") -> 1 | G10: =COUNTIFS('02_Feature_List'!$B$5:$B$141,$A10,'02_Feature_List'!$Q$5:$Q$141,"Done") -> 0 | H10: =IFERROR(G10/C10,0) -> 0
A11: E06 | B11: Knowledge & Context Fabric | C11: =COUNTIF('02_Feature_List'!$B$5:$B$141,$A11) -> 8 | D11: =COUNTIFS('02_Feature_List'!$B$5:$B$141,$A11,'02_Feature_List'!$J$5:$J$141,"Must") -> 7 | E11: =COUNTIFS('02_Feature_List'!$B$5:$B$141,$A11,'02_Feature_List'!$J$5:$J$141,"Should") -> 1 | F11: =COUNTIFS('02_Feature_List'!$B$5:$B$141,$A11,'02_Feature_List'!$J$5:$J$141,"Could") -> 0 | G11: =COUNTIFS('02_Feature_List'!$B$5:$B$141,$A11,'02_Feature_List'!$Q$5:$Q$141,"Done") -> 0 | H11: =IFERROR(G11/C11,0) -> 0
A12: E07 | B12: Agents — Understand | C12: =COUNTIF('02_Feature_List'!$B$5:$B$141,$A12) -> 7 | D12: =COUNTIFS('02_Feature_List'!$B$5:$B$141,$A12,'02_Feature_List'!$J$5:$J$141,"Must") -> 6 | E12: =COUNTIFS('02_Feature_List'!$B$5:$B$141,$A12,'02_Feature_List'!$J$5:$J$141,"Should") -> 0 | F12: =COUNTIFS('02_Feature_List'!$B$5:$B$141,$A12,'02_Feature_List'!$J$5:$J$141,"Could") -> 1 | G12: =COUNTIFS('02_Feature_List'!$B$5:$B$141,$A12,'02_Feature_List'!$Q$5:$Q$141,"Done") -> 0 | H12: =IFERROR(G12/C12,0) -> 0
A13: E08 | B13: Agents — Route & Prioritise | C13: =COUNTIF('02_Feature_List'!$B$5:$B$141,$A13) -> 4 | D13: =COUNTIFS('02_Feature_List'!$B$5:$B$141,$A13,'02_Feature_List'!$J$5:$J$141,"Must") -> 3 | E13: =COUNTIFS('02_Feature_List'!$B$5:$B$141,$A13,'02_Feature_List'!$J$5:$J$141,"Should") -> 1 | F13: =COUNTIFS('02_Feature_List'!$B$5:$B$141,$A13,'02_Feature_List'!$J$5:$J$141,"Could") -> 0 | G13: =COUNTIFS('02_Feature_List'!$B$5:$B$141,$A13,'02_Feature_List'!$Q$5:$Q$141,"Done") -> 0 | H13: =IFERROR(G13/C13,0) -> 0
A14: E09 | B14: Agents — Resolve | C14: =COUNTIF('02_Feature_List'!$B$5:$B$141,$A14) -> 6 | D14: =COUNTIFS('02_Feature_List'!$B$5:$B$141,$A14,'02_Feature_List'!$J$5:$J$141,"Must") -> 5 | E14: =COUNTIFS('02_Feature_List'!$B$5:$B$141,$A14,'02_Feature_List'!$J$5:$J$141,"Should") -> 1 | F14: =COUNTIFS('02_Feature_List'!$B$5:$B$141,$A14,'02_Feature_List'!$J$5:$J$141,"Could") -> 0 | G14: =COUNTIFS('02_Feature_List'!$B$5:$B$141,$A14,'02_Feature_List'!$Q$5:$Q$141,"Done") -> 0 | H14: =IFERROR(G14/C14,0) -> 0
A15: E10 | B15: Agents — Learn | C15: =COUNTIF('02_Feature_List'!$B$5:$B$141,$A15) -> 7 | D15: =COUNTIFS('02_Feature_List'!$B$5:$B$141,$A15,'02_Feature_List'!$J$5:$J$141,"Must") -> 5 | E15: =COUNTIFS('02_Feature_List'!$B$5:$B$141,$A15,'02_Feature_List'!$J$5:$J$141,"Should") -> 2 | F15: =COUNTIFS('02_Feature_List'!$B$5:$B$141,$A15,'02_Feature_List'!$J$5:$J$141,"Could") -> 0 | G15: =COUNTIFS('02_Feature_List'!$B$5:$B$141,$A15,'02_Feature_List'!$Q$5:$Q$141,"Done") -> 0 | H15: =IFERROR(G15/C15,0) -> 0
A16: E11 | B16: Human-in-the-Loop Console | C16: =COUNTIF('02_Feature_List'!$B$5:$B$141,$A16) -> 10 | D16: =COUNTIFS('02_Feature_List'!$B$5:$B$141,$A16,'02_Feature_List'!$J$5:$J$141,"Must") -> 10 | E16: =COUNTIFS('02_Feature_List'!$B$5:$B$141,$A16,'02_Feature_List'!$J$5:$J$141,"Should") -> 0 | F16: =COUNTIFS('02_Feature_List'!$B$5:$B$141,$A16,'02_Feature_List'!$J$5:$J$141,"Could") -> 0 | G16: =COUNTIFS('02_Feature_List'!$B$5:$B$141,$A16,'02_Feature_List'!$Q$5:$Q$141,"Done") -> 0 | H16: =IFERROR(G16/C16,0) -> 0
A17: E12 | B17: Governance, Security & Audit | C17: =COUNTIF('02_Feature_List'!$B$5:$B$141,$A17) -> 7 | D17: =COUNTIFS('02_Feature_List'!$B$5:$B$141,$A17,'02_Feature_List'!$J$5:$J$141,"Must") -> 5 | E17: =COUNTIFS('02_Feature_List'!$B$5:$B$141,$A17,'02_Feature_List'!$J$5:$J$141,"Should") -> 2 | F17: =COUNTIFS('02_Feature_List'!$B$5:$B$141,$A17,'02_Feature_List'!$J$5:$J$141,"Could") -> 0 | G17: =COUNTIFS('02_Feature_List'!$B$5:$B$141,$A17,'02_Feature_List'!$Q$5:$Q$141,"Done") -> 0 | H17: =IFERROR(G17/C17,0) -> 0
... A21: E16 | B21: Voice & Transcription | C21: =COUNTIF('02_Feature_List'!$B$5:$B$141,$A21) -> 7 | D21: =COUNTIFS('02_Feature_List'!$B$5:$B$141,$A21,'02_Feature_List'!$J$5:$J$141,"Must") -> 7 | E21: =COUNTIFS('02_Feature_List'!$B$5:$B$141,$A21,'02_Feature_List'!$J$5:$J$141,"Should") -> 0 | F21: =COUNTIFS('02_Feature_List'!$B$5:$B$141,$A21,'02_Feature_List'!$J$5:$J$141,"Could") -> 0 | G21: =COUNTIFS('02_Feature_List'!$B$5:$B$141,$A21,'02_Feature_List'!$Q$5:$Q$141,"Done") -> 0 | H21: =IFERROR(G21/C21,0) -> 0
B22: TOTAL | C22: =SUM(C6:C21) -> 137 | D22: =SUM(D6:D21) -> 119 | E22: =SUM(E6:E21) -> 16 | F22: =SUM(F6:F21) -> 2 | G22: =SUM(G6:G21) -> 0 | H22: =IFERROR(G22/C22,0) -> 0
A25: B. By owner and by week
A26: Owner | B26: Features | C26: Wk1 | D26: Wk2 | E26: Wk3 | F26: Wk4
A27: ARC | B27: =COUNTIF('02_Feature_List'!$L$5:$L$141,$A27) -> 20 | C27: =COUNTIFS('02_Feature_List'!$L$5:$L$141,$A27,'02_Feature_List'!$M$5:$M$141,1) -> 2 | D27: =COUNTIFS('02_Feature_List'!$L$5:$L$141,$A27,'02_Feature_List'!$M$5:$M$141,2) -> 6 | E27: =COUNTIFS('02_Feature_List'!$L$5:$L$141,$A27,'02_Feature_List'!$M$5:$M$141,3) -> 5 | F27: =COUNTIFS('02_Feature_List'!$L$5:$L$141,$A27,'02_Feature_List'!$M$5:$M$141,4) -> 7
A28: PM | B28: =COUNTIF('02_Feature_List'!$L$5:$L$141,$A28) -> 1 | C28: =COUNTIFS('02_Feature_List'!$L$5:$L$141,$A28,'02_Feature_List'!$M$5:$M$141,1) -> 0 | D28: =COUNTIFS('02_Feature_List'!$L$5:$L$141,$A28,'02_Feature_List'!$M$5:$M$141,2) -> 0 | E28: =COUNTIFS('02_Feature_List'!$L$5:$L$141,$A28,'02_Feature_List'!$M$5:$M$141,3) -> 0 | F28: =COUNTIFS('02_Feature_List'!$L$5:$L$141,$A28,'02_Feature_List'!$M$5:$M$141,4) -> 1
A29: BA | B29: =COUNTIF('02_Feature_List'!$L$5:$L$141,$A29) -> 5 | C29: =COUNTIFS('02_Feature_List'!$L$5:$L$141,$A29,'02_Feature_List'!$M$5:$M$141,1) -> 0 | D29: =COUNTIFS('02_Feature_List'!$L$5:$L$141,$A29,'02_Feature_List'!$M$5:$M$141,2) -> 1 | E29: =COUNTIFS('02_Feature_List'!$L$5:$L$141,$A29,'02_Feature_List'!$M$5:$M$141,3) -> 3 | F29: =COUNTIFS('02_Feature_List'!$L$5:$L$141,$A29,'02_Feature_List'!$M$5:$M$141,4) -> 1
A30: DEV-1 | B30: =COUNTIF('02_Feature_List'!$L$5:$L$141,$A30) -> 37 | C30: =COUNTIFS('02_Feature_List'!$L$5:$L$141,$A30,'02_Feature_List'!$M$5:$M$141,1) -> 11 | D30: =COUNTIFS('02_Feature_List'!$L$5:$L$141,$A30,'02_Feature_List'!$M$5:$M$141,2) -> 8 | E30: =COUNTIFS('02_Feature_List'!$L$5:$L$141,$A30,'02_Feature_List'!$M$5:$M$141,3) -> 10 | F30: =COUNTIFS('02_Feature_List'!$L$5:$L$141,$A30,'02_Feature_List'!$M$5:$M$141,4) -> 8
A31: DEV-2 | B31: =COUNTIF('02_Feature_List'!$L$5:$L$141,$A31) -> 40 | C31: =COUNTIFS('02_Feature_List'!$L$5:$L$141,$A31,'02_Feature_List'!$M$5:$M$141,1) -> 14 | D31: =COUNTIFS('02_Feature_List'!$L$5:$L$141,$A31,'02_Feature_List'!$M$5:$M$141,2) -> 12 | E31: =COUNTIFS('02_Feature_List'!$L$5:$L$141,$A31,'02_Feature_List'!$M$5:$M$141,3) -> 11 | F31: =COUNTIFS('02_Feature_List'!$L$5:$L$141,$A31,'02_Feature_List'!$M$5:$M$141,4) -> 3
A32: DEV-3 | B32: =COUNTIF('02_Feature_List'!$L$5:$L$141,$A32) -> 34 | C32: =COUNTIFS('02_Feature_List'!$L$5:$L$141,$A32,'02_Feature_List'!$M$5:$M$141,1) -> 12 | D32: =COUNTIFS('02_Feature_List'!$L$5:$L$141,$A32,'02_Feature_List'!$M$5:$M$141,2) -> 6 | E32: =COUNTIFS('02_Feature_List'!$L$5:$L$141,$A32,'02_Feature_List'!$M$5:$M$141,3) -> 10 | F32: =COUNTIFS('02_Feature_List'!$L$5:$L$141,$A32,'02_Feature_List'!$M$5:$M$141,4) -> 6
A35: C. By demo scene — proves that every scene is covered by delivered features
A36: Scene | B36: What it proves | C36: Features referencing it
A37: 1 | B37: Six systems, one twin — six emulated sources feeding one canonical model | C37: =COUNTIF('02_Feature_List'!$O$5:$O$141,"*"&$A37&"*") -> 22
A38: 2 | B38: An issue arrives — multi-channel intake including a real transcribed phone call | C38: =COUNTIF('02_Feature_List'!$O$5:$O$141,"*"&$A38&"*") -> 20
A39: 3 | B39: Who is this — identity resolved across four systems in under 2 seconds | C39: =COUNTIF('02_Feature_List'!$O$5:$O$141,"*"&$A39&"*") -> 18
A40: 4 | B40: What is it — classification, prioritisation, dedup, and the linked Jira defect | C40: =COUNTIF('02_Feature_List'!$O$5:$O$141,"*"&$A40&"*") -> 19
A41: 5 | B41: What do we know — cited context pack spanning four systems | C41: =COUNTIF('02_Feature_List'!$O$5:$O$141,"*"&$A41&"*") -> 22
A42: 6 | B42: Who should handle it — analyst recommendation from measured evidence | C42: =COUNTIF('02_Feature_List'!$O$5:$O$141,"*"&$A42&"*") -> 10
A43: 7 | B43: What should we do — draft, human approval, gated write-back | C43: =COUNTIF('02_Feature_List'!$O$5:$O$141,"*"&$A43&"*") -> 25
A44: 8 | B44: What did we learn — KB curation, pattern intelligence, analyst development areas | C44: =COUNTIF('02_Feature_List'!$O$5:$O$141,"*"&$A44&"*") -> 19
A47: D. Progress
A48: Status | B48: Features | C48: % of total
A49: Not started | B49: =COUNTIF('02_Feature_List'!$Q$5:$Q$141,$A49) -> 137 | C49: =IFERROR(B49/SUM($B$49:$B$53),0) -> 1
A50: In progress | B50: =COUNTIF('02_Feature_List'!$Q$5:$Q$141,$A50) -> 0 | C50: =IFERROR(B50/SUM($B$49:$B$53),0) -> 0
...

Sheet 02_Feature_List
A1: Feature List — ITR 4-Week POC
A2: Each row is a scope commitment. Update the Status column only.
A4: ID | B4: Epic | C4: Feature | D4: Description | E4: User story | F4: Acceptance criteria (Given / When / Then) | G4: Layer | H4: Component | I4: Depends on | J4: Priority | K4: Phase | L4: Owner | M4: Week | N4: Success metric | O4: Scene | P4: Plan task IDs | Q4: Status
A5: F-001 | B5: E01 | C5: One-command local stack | D5: Docker-compose bringing up Postgres+pgvector, Neo4j, Qdrant, Redis, MinIO, Temporal, API and console with healthchecks. | E5: As an engineer I want the whole stack up with one command so that I spend my time on the product, not on environment setup. | F5: GIVEN a clean machine WHEN I run docker compose up THEN all services report healthy within 3 minutes AND the console is reachable. | G5: Infrastructure | H5: docker-compose | I5: — | J5: Must | K5: POC | L5: DEV-1 | M5: 1 | N5: Cold start <3 min | O5: 1 | P5: W1-PLT-01 | Q5: Not started
A6: F-002 | B6: E01 | C6: Durable workflow engine | D6: Temporal service plus a Python worker, so long-running work survives restarts, 429s and human wait time. | E6: As an engineer I want long-running jobs to be resumable so that a rate limit or a restart never loses ingestion progress. | F6: GIVEN a backfill in flight WHEN the worker is killed THEN it resumes from the last checkpoint with no duplicate or missing records. | G6: Infrastructure | H6: Temporal | I6: — | J6: Must | K6: POC | L6: DEV-1 | M6: 1 | N6: Zero data loss on kill -9 | O6: 2 | P6: W1-PLT-02 | Q6: Not started
A7: F-003 | B7: E01 | C7: Repo structure & layering lint | D7: Monorepo with adapters/, canonical/, context/, agents/, api/, console/, gen/, evals/. Lint rule forbids agents/ importing adapters/. | E7: As an architect I want the 80/20 vendor split enforced by tooling so that the canonical core stays genuinely vendor-agnostic. | F7: GIVEN a PR where an agent imports a Zendesk module WHEN CI runs THEN the build fails with a clear message. | G7: Infrastructure | H7: CI lint | I7: — | J7: Must | K7: POC | L7: DEV-3 | M7: 1 | N7: 0 layering violations on main | O7: — | P7: W1-PLT-03 | Q7: Not started
A8: F-004 | B8: E01 | C8: CI pipeline | D8: Ruff, mypy, pytest unit and integration against compose services, docker build. Required check on main. | E8: As a team we want a red build to block merge so that main is always demoable. | F8: GIVEN a failing test WHEN a PR is opened THEN merge is blocked AND the pipeline completes in under 8 minutes. | G8: Infrastructure | H8: GitHub Actions | I8: — | J8: Must | K8: POC | L8: DEV-3 | M8: 1 | N8: Pipeline <8 min | O8: — | P8: W1-PLT-04 | Q8: Not started
A9: F-005 | B9: E01 | C9: Seed & teardown | D9: make seed / make reset. Idempotent, loads reference data plus a 200-ticket smoke corpus. | E9: As a new engineer I want a working world in one command so that onboarding is measured in minutes. | F9: GIVEN an empty database WHEN I run make seed THEN a queryable 200-ticket world exists in under 10 minutes. | G9: Infrastructure | H9: scripts | I9: Reference data | J9: Must | K9: POC | L9: DEV-1 | M9: 1 | N9: New machine to working world <10 min | O9: 1 | P9: W1-PLT-05 | Q9: Not started
A10: F-006 | B10: E01 | C10: Tracing & structured logs | D10: OpenTelemetry traces and JSON logs with run_id and trace_id propagated from ingest through agent to console. | E10: As an engineer I want one trace ID to follow a ticket end to end so that debugging an agent decision takes minutes, not hours. | F10: GIVEN any ticket WHEN I search its trace ID THEN I see every ingestion, retrieval, LLM call and console action in order. | G10: Observability | H10: OTel | I10: — | J10: Must | K10: POC | L10: DEV-3 | M10: 1 | N10: 100% of pipeline steps traced | O10: 7, 8 | P10: W1-PLT-06 | Q10: Not started
A11: F-007 | B11: E01 | C11: Config & secrets management | D11: pydantic-settings config, .env for local, KMS stub for cloud. No secret in code or logs. | E11: As a security reviewer I want no credentials in the repository so that the VPC deployment story is credible. | F11: GIVEN a repository scan WHEN secret detection runs THEN zero credentials are found. | G11: Infrastructure | H11: config | I11: — | J11: Must | K11: POC | L11: DEV-3 | M11: 1 | N11: 0 secrets in repo | O11: — | P11: W1-PLT-03 | Q11: Not started
A12: F-008 | B12: E01 | C12: Reproducible tagged release | D12: Pinned dependencies and a tagged release that rebuilds byte-identically for the demo. | E12: As a presenter I want the demo build to be reproducible so that nothing changes underneath me on demo day. | F12: GIVEN the release tag WHEN I rebuild on a clean machine THEN I get the same image set. | G12: Infrastructure | H12: release | I12: — | J12: Must | K12: POC | L12: DEV-1 | M12: 4 | N12: Reproducible build verified | O12: — | P12: W4-PLT-01 | Q12: Not started
A13: F-009 | B13: E01 | C13: Client-VPC packaging readiness | D13: Every component is open source and container-packaged; no managed-only service is load-bearing. | E13: As a prospect CISO I want the stack to run inside my own VPC so that my support data never leaves my boundary. | F13: GIVEN the component inventory WHEN reviewed THEN every store and service has a self-hostable container image. | G13: Infrastructure | H13: architecture | I13: — | J13: Should | K13: POC | L13: DEV-1 | M13: 4 | N13: 0 managed-only dependencies | O13: — | P13: W4-PLT-02 | Q13: Not started
A14: F-010 | B14: E02 | C14: Reference data load (Batch A) | D14: Load company profiles, L1 categories, 100 problem classes, 20 variant axes, channels, ticket fields, lifecycle states, resolution paths and distributions. | E14: As a data engineer I want the reference taxonomy in the database so that every generated ticket is traceable to a class and a variant. | F14: GIVEN the Master Spec workbook WHEN Batch A runs THEN row counts reconcile exactly AND a checksum is recorded. | G14: Data | H14: gen/batch_a | I14: Master Spec sheets 03-07, 12-17 | J14: Must | K14: POC | L14: DEV-1 | M14: 1 | N14: 100% reconciliation | O14: 1 | P14: W1-SYN-01 | Q14: Not started
A15: F-011 | B15: E02 | C15: Synthetic world (Batch B) | D15: 1,200 accounts, 4,800 contacts, 240 agents with full profile schema and skills matrix, 900 KB articles with deliberate coverage gaps. | E15: As a demo audience I want the world to look like a real support organisation so that the numbers on screen are believable. | F15: GIVEN Batch B WHEN complete THEN volumes match the volume plan AND agent skill scarcity follows the specified distribution. | G15: Data | H15: gen/batch_b | I15: Batch A | J15: Must | K15: POC | L15: DEV-3 | M15: 1 | N15: Volumes match plan exactly | O15: 1, 3 | P15: W1-SYN-02 | Q15: Not started
A16: F-012 | B16: E02 | C16: Scenario template library (Batch C) | D16: 2,000 pre-expanded scenario templates covering all 100 problem classes across the 20 variant axes. | E16: As an architect I want scenario coverage to be provable so that no class is silently unrepresented. | F16: GIVEN the loaded templates WHEN coverage is computed THEN 100 of 100 classes are represented AND demo scenarios are tagged. | G16: Data | H16: gen/batch_c | I16: scenario_variants_2000.csv | J16: Must | K16: POC | L16: DEV-1 | M16: 1 | N16: 100/100 class coverage | O16: 1 | P16: W1-SYN-03 | Q16: Not started
... A141: F-137 | B141: E16 | C141: Audio and transcript PII handling | D141: Transcripts are redacted before any LLM call exactly like text. Audio is served only via short-lived signed URLs, never sent to a model, and excluded from every index. | E141: As a data protection officer I want call recordings treated as personal data even when synthetic so that the habit is correct before real data arrives. | F141: GIVEN the audit WHEN run THEN no audio object was sent to a model and every access used a signed URL. | G141: Governance | H141: governance/pii | I141: F-134 | J141: Must | K141: POC | L141: DEV-2 | M141: 4 | N141: 0 audio objects sent to a model | O141: 2 | P141: W4-EVL-02 | Q141: Not started

Sheet 03_Epics
A1: Epics
A2: Each epic traces back to a recorded decision. Nothing here is invented for the sake of a plan.
A4: Epic | B4: Name | C4: What it delivers | D4: Accountable | E4: Traces back to
A5: E01 | B5: Platform & Deployment | C5: Open-source stack that runs from one command and could redeploy into a client VPC unchanged. | D5: DEV-1 | E5: 21-Jul: single-tenant, customer-hosted
A6: E02 | B6: Synthetic Data Corpus | C6: A credible support world — 6,000 tickets, 500 deep multi-channel threads, ground-truth labelled. | D6: DEV-1 | E6: 23-Jul: contextual richness over volume
A7: E03 | B7: Canonical Model & Digital Twin | C7: Vendor-agnostic canonical entities. Agents never see a vendor payload. | D7: DEV-2 | E7: 21-Jul & 29-Jul: canonical digital twin
A8: E04 | B8: Source Systems, Emulation & Ingestion | C8: Six emulated systems with faithful replica schemas and mock APIs; six adapters against one contract; reconciliation. | D8: DEV-2 | E8: 17-Jul & 21-Jul: Zendesk beachhead, vendor-agnostic core — now demonstrable
A9: E05 | B9: Identity Resolution & 360 | C9: Resolve a requester across Zendesk, Workday, Entra and Salesforce, with evidence. | D9: DEV-2 | E9: 21-Jul: Customer/User 360 in the agentic brain
A10: E06 | B10: Knowledge & Context Fabric | C10: Four stores plus hybrid retrieval, compiled into a cited, PII-filtered context pack. The moat. | D10: ARC | E10: 29-Jul: Neo4j + Postgres + vector + Redis
A11: E07 | B11: Agents — Understand | C11: Listen, enrich, classify, deduplicate. | D11: ARC | E11: 22-Jul: hybrid orchestration of targeted agents
A12: E08 | B12: Agents — Route & Prioritise | C12: SLA-aware prioritisation and evidence-based assignment driven by the analyst capability engine. | D12: DEV-2 | E12: 21-Jul: no workforce management
A13: E09 | B13: Agents — Resolve | C13: Cited draft resolutions and structured escalation. Recommendation only. | D13: ARC | E13: 29-Jul: classify + intention, not action
A14: E10 | B14: Agents — Learn | C14: KB curation and weekly pattern intelligence — the compounding loop. | D14: ARC | E14: 21-Jul: AI-assisted documentation; KB curation
A15: E11 | B15: Human-in-the-Loop Console | C15: Approval queue, ticket 360, citations, explainers, audit viewer, digest. | D15: DEV-3 | E15: 23-Jul: admin/monitoring UI only, no end-user UI
... A20: E16 | B20: Voice & Transcription | C20: Spoken dialogue generated, synthesised to audio, transcribed by a real ASR engine, with confidence carried through the pipeline. | D20: DEV-1 | E20: v2 client direction — validates and upgrades the narration-to-audio assumption

Sheet 04_Agent_Specs
A1: Agent Pipeline Specification
A2: 12 agents, 4 stages, LangGraph-orchestrated with Temporal durability. Eleven are built in full this sprint; QA/Verifier is scoped to sampled runs only.
A4: # | B4: Agent | C4: Stage | D4: Input | E4: Output | F4: Model tier | G4: Guardrail | H4: HITL gate | I4: Evaluation metric | J4: POC?
A5: 1 | B5: Listener | C5: A · Ingest & Understand | D5: Webhook event or export page | E5: Canonical records, idempotent on external_id | F5: None (deterministic) | G5: No LLM in the hot path; dedup on external_id + generated_ts; resumable via Temporal | H5: — | I5: Ingestion completeness vs source count; zero drops under burst | J5: Yes
A6: 2 | B6: Context Enricher | C6: A · Ingest & Understand | D6: Case + tenant graph + vector index + Workday bridge | E6: Typed, cited, PII-filtered context pack | F6: Sonnet | G6: Retrieval score threshold; raises low-context flag rather than proceeding | H6: — | I6: Citation coverage; retrieval precision@k | J6: Yes
A7: 3 | B7: Triage / Classifier | C7: A · Ingest & Understand | D7: Case text + context pack | E7: intent, category, priority, sentiment, language, confidence | F7: Haiku (→Sonnet on low confidence) | G7: Below threshold means 'needs human triage', never a guess; consumes Zendesk AI fields as prior; prompt-injection guard | H7: — | I7: Macro-F1 vs ground truth; agreement with Zendesk AI | J7: Yes
A8: 4 | B8: Dedup & Linker | C8: A · Ingest & Understand | D8: Case embedding + fingerprint + open-ticket index | E8: Merge or link proposals with similarity score | F8: Haiku | G8: Never auto-merges. High score suggests a merge for human confirmation; mid score links only | H8: — | I8: Precision and recall on labelled pairs | J8: Yes
A9: 5 | B9: Prioritisation | C9: B · Route & Prioritise | D9: Case + SLAClock events + account tier | E9: Priority score, breach-risk flag, reason | F9: Sonnet (explanation only) | G9: SLA maths is deterministic; the LLM writes prose and can never change the number | H9: — | I9: Breach-risk lead time; prediction precision | J9: Yes
A10: 6 | B10: Assignment / Load-Balancer | C10: B · Route & Prioritise | D10: Intent + agent skills + capacity + schedule | E10: Assignment proposal, ranked alternatives, rationale | F10: Sonnet | G10: Shadow mode first; reads existing triggers to avoid conflicting with customer automation | H10: Routing gate | I10: Acceptance rate; reassignment rate; load variance | J10: Yes
A11: 7 | B11: Resolution | C11: C · Resolve | D11: Context pack + ResolutionRecord retrieval + KB + runbooks | E11: Cited draft action(s) with confidence | F11: Sonnet (→Opus on hard cases) | G11: Grounded strictly in retrieved evidence; injection-resistant; no uncited claim may be rendered | H11: Every write | I11: Approval acceptance rate; edit distance; CSAT proxy | J11: Yes
A12: 8 | B12: Escalation | C12: C · Resolve | D12: Case + failed-match signal | E12: Structured escalation summary + suggested owner | F12: Sonnet | G12: Guarantees every ticket has a path — a draft or an escalation, never neither | H12: — | I12: Escalation appropriateness; time to owner | J12: Yes
A13: 9 | B13: Action Executor | C13: C · Resolve | D13: Approved action + human decision record | E13: External write + audit entry + ResolutionRecord | F13: None (deterministic) | G13: Runs only after approval; retries with backoff on 429; no ungated code path exists | H13: Post-approval only | I13: Write success rate; audit completeness | J13: Yes
A14: 10 | B14: KB Curator | C14: D · Learn | D14: ResolutionRecord + existing KB | E14: Draft article or update proposal | F14: Sonnet | G14: Drafts only; publication requires human approval; dedupe threshold against existing articles | H14: Publish gate | I14: Article acceptance rate; KB coverage growth | J14: Yes
A15: 11 | B15: QA / Verifier | C15: D · Learn | D15: Sampled agent runs + traces | E15: Quality score, flagged runs, calibration report | F15: Opus (sampled) | G15: Samples a percentage of runs plus all low-confidence ones | H15: — | I15: Hallucination rate; confidence calibration; injection catch rate | J15: Partial
A16: 12 | B16: Pattern Miner | C16: D · Learn | D16: CaseEvent history + categories + derivations | E16: Weekly digest: patterns, deflection candidates, KB gaps | F16: Sonnet (batch) | G16: Batch and offline; advisory only, never acts | H16: — | I16: Pattern precision; analyst-rated usefulness | J16: Yes
B18: Model tiering: Haiku for high-volume classification · Sonnet for orchestration and drafting · Opus reserved for hard reasoning and sampled QA. All calls run through one reasoning-service abstraction and are PII-redacted before leaving the boundary.

Sheet 05_Data_Entities
A1: Canonical Data Entities
A2: Vendor-agnostic core. Zendesk field names shown for mapping only — no agent ever reads a vendor payload.
A4: Entity | B4: Group | C4: Purpose | D4: Key fields | E4: Zendesk source mapping | F4: POC volume
A5: Case | B5: Core ticketing | C5: The ticket. Canonical, never vendor-shaped. | D5: id, external_id, status_category, priority, type, channel_id, requester_id, assignee_id, team_id, account_id, intent_id, sla_policy_id, tags[], custom_fields{}, generated_ts | E5: ticket.* — status, priority, via.channel, group_id, organization_id, ticket_form_id | F5: 6,000
A6: CaseEvent | B6: Core ticketing | C6: One row per change — makes history replayable and audit real. | D6: case_id, actor_id, event_type, field_name, from_value, to_value, occurred_at | E6: Ticket Audits / Incremental ticket_events export | F6: ~48,000
A7: Comment | B7: Core ticketing | C7: Public replies and internal notes. Immutable. | D7: case_id, author_id, public, body, html, via, created_at | E7: ticket comments (public / internal note) | F7: ~30,000
A8: Attachment | B8: Core ticketing | C8: Evidence — logs, CSVs, invoices, screenshots. | D8: comment_id, file_name, content_type, size, url, inline, malware_scan_result | E8: comment attachments | F8: ~4,000
A9: SatisfactionRating | B9: Core ticketing | C9: CSAT, feeding ResolutionRecord quality signals. | D9: case_id, score, comment, reason_code, requester_id, assignee_id | E9: satisfaction_ratings | F9: ~2,400
A10: Actor | B10: People & org | C10: Any human — end user, agent or admin. | D10: external_id, role, name, email, locale, time_zone, account_id, default_team_id, worker_id, skills[], capacity | E10: users.* | F10: ~5,040
A11: Team | B11: People & org | C11: Queue or group. | D11: id, name, description, is_public, default | E11: groups | F11: ~40
A12: TeamMembership | B12: People & org | C12: Agent-to-team many-to-many with one default each. | D12: actor_id, team_id, default | E12: group_memberships | F12: ~400
A13: Account | B13: People & org | C13: Customer organisation with tier and domains. | D13: external_id, name, domain_names[], default_team_id, cost_center_id, tags[] | E13: organizations | F13: 1,200
A14: Channel | B14: Config & rules | C14: Where the interaction happened. 12 channels modelled. | D14: id, type, source_ref | E14: ticket.via.channel | F14: 12
A15: Category / Intent | B15: Config & rules | C15: The taxonomy: 10 L1 categories, 100 problem classes. | D15: id, name, parent_id, taxonomy, intent_confidence, sentiment, language | E15: triage intent field / custom taxonomy | F15: 110
... A36: call_recording | B36: Voice | C36: The audio artefact and its transcription metadata. | D36: case_id, audio_uri, duration_sec, speakers[], tts_model, asr_model, asr_confidence_avg, word_error_rate | E36: gen/voice Batch K | F36: 200

Sheet 06_Integrations_APIs
A1: Integrations, APIs & Constraints
A2: The external surface. Rate limits are design constraints, not footnotes.
A4: System | B4: Capability | C4: Endpoints / mechanism | D4: Scopes / auth | E4: Constraint that shapes design | F4: POC use
A5: Zendesk | B5: Metadata discovery | C5: Ticket Fields, Forms, Triggers, Automations, Macros, Views, Custom Objects, Brands | D5: read (+triggers, automations, macros) | E5: Configuration varies widely per tenant — this is why discovery is dynamic rather than hard-coded | F5: Inventory report, ≥98% accuracy
A6: Zendesk | B6: Historical backfill | C6: Incremental Exports (tickets, users, orgs, ticket_events, metric_events); Search Export; sideloads | D6: tickets:read, users:read, organizations:read | E6: Incremental exports limited to ~10 per minute — everything must be cursor-based and resumable | F6: 6,000-ticket backfill via Temporal
A7: Zendesk | B7: Near-real-time events | C7: Event-subscription webhooks with HMAC signing | D7: webhooks:write | E7: Comment bodies are not in the payload and must be fetched — a second call per event | F7: Live ticket demo path
A8: Zendesk | B8: Knowledge | C8: Help Center articles, sections, search | D8: hc:read, hc:write | E8: Drafts are safe; publication is the gated act | F8: 900 seeded articles; curator drafts
A9: Zendesk | B9: Write-back | C9: Ticket update, public and internal comments, macro apply, status change, KB draft, merge | D9: tickets:write, hc:write | E9: Ticket update capped near 100 per minute — batch and back off | F9: Approved actions only, HITL-gated
A10: Zendesk | B10: Rate limits (all) | C10: Account-wide quota by plan | D10: — | E10: 200–700 requests/minute by plan (2,500 with the High Volume add-on) — queue and back off inside Temporal | F10: Throttle injection test
A11: Zendesk emulator | B11: Round-trip proof | C11: Our own Zendesk emulator, serving the corpus in native shape | D11: OAuth stub or API token | E11: No external dependency exists. The emulator can be made to return 429s, 500s and partial pages on demand, which a real sandbox cannot. | F11: Write-back target for every approved action
A12: Workday | B12: Employee enrichment | C12: Extract-based bridge for the POC (MCP connector optional later) | D12: read-only | E12: Dev environments hold structure but no meaningful ticket history — synthetic data remains necessary | F12: 200-employee Dr_Pepper extract
A13: Anthropic | B13: Reasoning service | C13: Messages API, Haiku / Sonnet / Opus | D13: API key, per-tenant metering | E13: Cost is the constraint. Haiku-first tiering; hard ceiling in the generation harness | F13: Generation + all agents
A14: Anthropic | B14: Corpus generation | C14: Batched offline generation for Stage B narratives | D14: API key | E14: Batch overnight; 100-thread pilot before committing full spend | F14: 500 golden + 1,500 fill threads
A15: Kaggle 100k dataset | B15: Distribution calibration | C15: Offline analysis only | D15: — | E15: Real data sets the targets; synthetic data hits them with labels attached | F15: Gate G-14
... A17: MCP connectors | B17: Cross-system context | C17: Slack, Teams, docs, HRIS | D17: per connector | E17: N+M not N×M — added per tenant need, not speculatively | F17: Phase 2

Sheet 07_NonFunctional
A1: Non-Functional Requirements
A2: Every target has a measurement method and a first-report date. A target without a measurement is an aspiration.
A4: # | B4: Category | C4: Requirement | D4: Target | E4: How it is measured | F4: First reported
A5: 1 | B5: Performance | C5: Context pack compilation | D5: p95 < 2 s | E5: Traced end to end on demo hardware, not a developer laptop | F5: D10 (G2)
A6: 2 | B6: Performance | C6: Full pipeline, webhook to approval-pending | D6: p95 < 30 s | E6: Traced end to end | F6: D15 (G3)
A7: 3 | B7: Performance | C7: Warm-cache context fetch | D7: p95 < 200 ms | E7: Redis instrumentation | F7: D11
A8: 4 | B8: Performance | C8: 3-hop graph query | D8: < 200 ms | E8: Neo4j query profiling | F8: D05
A9: 5 | B9: Performance | C9: Cold start of the full stack | D9: < 3 min | E9: Timed docker compose up | F9: D05 (G1)
A10: 6 | B10: Performance | C10: Empty machine to demo-ready | D10: < 45 min | E10: Timed rebuild by a second engineer | F10: D19
A11: 7 | B11: Scalability | C11: Corpus size supported | D11: 6,000 tickets, ~90k chunks | E11: Load test at corpus scale | F11: D12
A12: 8 | B12: Reliability | C12: Ingestion under interruption | D12: 0 loss, 0 duplication | E12: Kill -9 during backfill; reconcile against manifest | F12: D07
A13: 9 | B13: Reliability | C13: Ingestion under rate limiting | D13: 0 loss | E13: Sustained 429 injection | F13: D13
A14: 10 | B14: Security | C14: PII reaching an LLM | D14: 0 instances | E14: 200-ticket trace audit plus adversarial suite | F14: D18
A15: 11 | B15: Security | C15: Successful prompt injections | D15: 0 | E15: 50-case adversarial suite | F15: D18
A16: 12 | B16: Security | C16: Cross-tenant reads | D16: 0 | E16: Cross-tenant probe, logged as a security event | F16: D10
... A48: 44 | B48: Governance | C48: Ambiguity about emulated vs live in the UI | D48: 0 | E48: User test: an unfamiliar viewer correctly identifies emulation | F48: D16

Sheet 08_Metrics_KPIs
A1: Metrics & KPIs
A2: Every number this programme quotes, with its source. If it is not here, do not put it on a slide.
A4: Metric | B4: Category | C4: Target | D4: Why this target | E4: Measurement | F4: Owner
A5: Triage macro-F1 | B5: Model quality | C5: ≥ 0.80 | D5: Below this, mis-routing persists and the core claim fails | E5: Held-out account-level split vs case_label | F5: ARC
A6: Dedup precision / recall | B6: Model quality | C6: ≥ 0.85 / ≥ 0.70 | D6: Precision matters more — a false merge destroys trust instantly | E6: Labelled near-duplicate pairs | F6: DEV-3
A7: Identity match rate | B7: Model quality | C7: ≥ 95% | D7: Below this the 360 view is unreliable and scene 3 collapses | E7: Synthetic joins with known answers | F7: DEV-2
A8: Citation coverage | B8: Groundedness | C8: ≥ 90% | D8: An uncited claim is indistinguishable from a hallucination | E8: Context pack inspection | F8: ARC
A9: Context pack latency p95 | B9: Performance | C9: < 2 s | D9: Above this the demo feels sluggish and the moat feels theoretical | E9: Traced on demo hardware | F9: DEV-1
A10: Assignment acceptance | B10: Usefulness | C10: ≥ 80% | D10: The threshold at which a team lead stops second-guessing every suggestion | E10: vs labelled correct queue | F10: DEV-2
A11: Usable draft rate | B11: Usefulness | C11: ≥ 30% | D11: One in three tickets pre-drafted is a material handling-time saving | E11: Human review of a sample | F11: ARC
A12: KB draft acceptance | B12: Usefulness | C12: ≥ 50% | D12: Below half, curation creates review work rather than saving it | E12: Human review | F12: ARC
A13: Pattern detection recall | B13: Usefulness | C13: 10 of 10 seeded | D13: Proves the miner finds patterns rather than being shown them | E13: Seeded recurrence patterns | F13: DEV-1
A14: Inventory accuracy | B14: Connector | C14: ≥ 98% | D14: Automatic discovery is the anti-consulting-project claim | E14: vs the configuration the emulator was seeded with | F14: DEV-2
A15: PII leaks | B15: Security | C15: 0 | D15: Not a target so much as a precondition for showing anyone | E15: Adversarial suite + trace audit | F15: DEV-2
... A29: Assignment evidence coverage | B29: Analyst | C29: 100% | D29: An unexplained recommendation is one a team lead will ignore | E29: Every claim click-through to its tickets | F29: DEV-3

Sheet 09_Out_of_Scope
A1: Explicitly Out of Scope
A2: Read this before agreeing to anything in a meeting. Each exclusion is a recorded decision, not an omission.
A4: Excluded | B4: Why | C4: Decision source | D4: Where it goes
A5: Autonomous (non-HITL) execution | B5: Output is classification and stated intention; execution is deferred. There is not even a disabled autonomous path in the codebase — that is deliberate, because a disabled path is a path. | C5: 29-Jul MoM | D5: MVP Phase 2
A6: Salesforce Service Cloud adapter | B6: Higher integration risk; customers run multiple interlinked clouds. Zendesk is more standalone with a broader install base. | C6: 21-Jul MoM | D6: MVP Phase 2
A7: ServiceNow / Jira Service Management adapters | B7: Same adapter contract; additive work that changes nothing in the canonical core. | C7: 22-Jul design | D7: GA
A8: End-user chatbot or deflection UI | B8: No dedicated end-user interface in the MVP; the product embeds into existing channels. | C8: 23-Jul MoM | D8: Not planned
A9: Voice channel | B9: Out of MVP scope. Modelled in the corpus as a channel, not integrated. | C9: 22-Jul design | D9: GA
A10: Multi-tenant SaaS | B10: Single-tenant customer-hosted deployment avoids the SOC 2 and compliance burden at this stage. | C10: 21-Jul MoM | D10: GA
A11: Langfuse / LangMem governance stack | B11: Deferred pending a technical spike — the tooling was judged new with limited community support. A lightweight internal audit table substitutes and is the migration target. | C11: 28-Jul MoM | D11: MVP Phase 2
A12: Workforce management (shifts, rosters, round-robin) | B12: Explicitly excluded as a scope-expansion risk. Assignment uses skills and capacity only. | C12: 21-Jul MoM | D12: Not planned
A13: Predictive volume forecasting | B13: Not on the demo path and not what the POC is trying to prove. | C13: 22-Jul design | D13: GA
A14: Process-mining digital twin | B14: Interesting, but it is not what this demo proves. | C14: 22-Jul design | D14: GA
A15: Corpus scale-out to 20,000 tickets | B15: Gated on the 18 validation gates passing at 6,000. Depth before breadth. | C15: Master Spec §11 | D15: MVP Phase 2
... A27: Analyst performance management, ranking or appraisal | B27: Capability signals exist to route work well and to surface where someone would benefit from support. Turning them into a ranking or appraisal tool is a different product with different ethics, and it is not this one. | C27: v2 decision | D27: Not planned

Sheet 10_Source_Systems
A1: Source Systems — Emulated
A2: Six systems, each with a faithful replica of its native schema and a mock API speaking the real endpoint shapes. Synthetic data, real integration path. Never presented as live.
A4: System | B4: Role in the story | C4: Native objects modelled | D4: API behaviour reproduced | E4: Adapter scope | F4: Write-back | G4: Canonical entities produced
A5: Zendesk | B5: Primary ticketing — the beachhead confirmed 17-Jul and 21-Jul. | C5: tickets · users · organizations · ticket_comments · ticket_audits · ticket_metric_events · groups · macros · triggers · ticket_fields · custom_object_records (assets) · hc_articles | D5: Cursor incremental export with end_of_stream · sideloads · HMAC-signed event webhooks · account-wide rate limit returning real 429 + Retry-After | E5: Metadata · backfill · events · actions | F5: YES — gated | G5: Case · Comment · CaseEvent · SLAClock · Actor · Team · Account · KnowledgeArticle · Asset
A6: Salesforce Service Cloud | B6: A second CRM in a genuinely different shape. Its whole job is to prove the canonical core is not Zendesk-shaped. | C6: Case · Contact · Account · User · CaseComment · EmailMessage · Entitlement · Knowledge__kav — 18-character case-safe IDs, zero-padded CaseNumber | D6: SOQL-ish query with nextRecordsUrl paging · composite retrieval · a daily API call ceiling that actually depletes | E6: Metadata · backfill | F6: No | G6: Case (secondary) · Account · Actor · Entitlement · KnowledgeArticle
A7: Workday | B7: Org, roles, skills and employment — the backbone of both the employee-service story and the analyst capability model. | C7: Worker · Supervisory_Organization · Job_Profile · Cost_Center · Worker_Skill · Position — Workday field naming, two extract variants | D7: Report-as-a-service extract endpoints serving both column-name variants as a reconciliation fixture | E7: Metadata · backfill | F7: No | G7: Worker · OrgUnit · JobProfile · CostCenter · analyst skills and org
A8: Jira | B8: Where hard tickets escalate to engineering — and where support usually cannot see. | C8: issues (PROJECT-nnn keys) · projects · issue_comments · changelog · issue_links · sprints · users | D8: REST search with startAt/maxResults · changelog expansion · issue links | E8: Metadata · backfill | F8: No | G8: Escalation issues linked to Case · engineering comments
A9: Microsoft Entra | B9: Identity, groups and devices — the org structure Workday does not fully capture. Flagged as a gap on 29-Jul. | C9: users (GUID) · groups · group_members · devices · sign_in_logs | D9: Graph-style $select / $filter / @odata.nextLink paging | E9: Metadata · backfill | F9: No | G9: Group membership · devices · sign-in context for identity resolution
A10: Slack / Teams | B10: Where resolution actually happens, off-platform. The 22-Jul MoM flagged that real resolutions often never reach Zendesk. | C10: channels (incl. Connect) · messages (epoch.micro ts) · threads via thread_ts · users · reactions · files | D10: conversations.history and conversations.replies with cursor paging and thread semantics | E10: Metadata · backfill | F10: No | G10: Off-platform Comments linked to Case · participants
A12: FIDELITY RULES — Zendesk uses bigint ids and generated_ts ordering; Salesforce uses 18-character case-safe ids and zero-padded CaseNumber; Jira uses PROJECT-nnn keys; Entra uses GUIDs; Slack uses epoch.microsecond timestamp strings with thread_ts reply semantics. These are not decoration: an adapter written against tidy UUIDs everywhere breaks on contact with a real tenant, and we would not find out until it mattered.
A14: CHAOS MODE — every emulator supports ?chaos=429|500|slow|partial, so resilience is tested honestly rather than hoped for. Showing this to a technical buyer is worth more than claiming it.
A16: WHAT WE DO NOT CLAIM — these are emulated systems carrying synthetic data, with is_synthetic on every row at every layer, labelled on the connections screen, in the corpus datasheet and in every deck. The claim is narrower and stronger: the adapter, ingestion, canonical and context layers are production-shaped and would work against the real systems unmodified, because they are speaking to the real API shapes today.
A18: PHASE 2 MIGRATION — replacing an emulator with a real tenant is roughly a day per system: swap the base URL, swap the auth, keep everything else. The emulators then survive as the integration test harness, which is worth more after the sprint than during it.
